Workbook

Sheet iris_data_csv
A2: sepall | B2: sepalw | C2: petall | D2: petalw | E2: clase
A3: 5.1 | B3: 3.5 | C3: 1.4 | D3: 0.2 | E3: Iris-setosa
A4: 4.9 | B4: 3 | C4: 1.4 | D4: 0.2 | E4: Iris-setosa
A5: 4.7 | B5: 3.2 | C5: 1.3 | D5: 0.2 | E5: Iris-setosa
A6: 4.6 | B6: 3.1 | C6: 1.5 | D6: 0.2 | E6: Iris-setosa
A7: 5 | B7: 3.6 | C7: 1.4 | D7: 0.2 | E7: Iris-setosa
A8: 5.4 | B8: 3.9 | C8: 1.7 | D8: 0.4 | E8: Iris-setosa
A9: 4.6 | B9: 3.4 | C9: 1.4 | D9: 0.3 | E9: Iris-setosa
A10: 5 | B10: 3.4 | C10: 1.5 | D10: 0.2 | E10: Iris-setosa
A11: 4.4 | B11: 2.9 | C11: 1.4 | D11: 0.2 | E11: Iris-setosa
A12: 4.9 | B12: 3.1 | C12: 1.5 | D12: 0.1 | E12: Iris-setosa
A13: 5.4 | B13: 3.7 | C13: 1.5 | D13: 0.2 | E13: Iris-setosa
A14: 4.8 | B14: 3.4 | C14: 1.6 | D14: 0.2 | E14: Iris-setosa
... A152: 5.9 | B152: 3 | C152: 5.1 | D152: 1.8 | E152: Iris-virginica

Sheet discretizacion
A1: Discretizacion
A2: Criterio: para cada atributo, umbral1 = minimo + (maximo-minimo)/3 y umbral2 = minimo + 2*(maximo-minimo)/3 (3 partes de ancho igual sobre el rango de iris.data.csv). value<=umbral1 -> chico; umbral1<value<=umbral2 -> mediano; value>umbral2 -> grande. ID3 necesita atributos nominales, por eso se discretiza; esta clasificacion sale unicamente de iris.data.csv (min y max de cada columna), sin usar ningun otro archivo.
A4: Umbrales usados (calculados con MIN/MAX de iris_data_csv):
A5: atributo | B5: minimo | C5: maximo | D5: umbral1 = min+(max-min)/3 | E5: umbral2 = min+2(max-min)/3
A6: sepall | B6: =MIN(iris_data_csv!A3:A152) -> 4.3 | C6: =MAX(iris_data_csv!A3:A152) -> 7.9 | D6: =B6+(C6-B6)/3 -> 5.5 | E6: =B6+2*(C6-B6)/3 -> 6.7
A7: sepalw | B7: =MIN(iris_data_csv!B3:B152) -> 2 | C7: =MAX(iris_data_csv!B3:B152) -> 4.4 | D7: =B7+(C7-B7)/3 -> 2.8 | E7: =B7+2*(C7-B7)/3 -> 3.6
A8: petall | B8: =MIN(iris_data_csv!C3:C152) -> 1 | C8: =MAX(iris_data_csv!C3:C152) -> 6.9 | D8: =B8+(C8-B8)/3 -> 2.9666667 | E8: =B8+2*(C8-B8)/3 -> 4.9333333
A9: petalw | B9: =MIN(iris_data_csv!D3:D152) -> 0.1 | C9: =MAX(iris_data_csv!D3:D152) -> 2.5 | D9: =B9+(C9-B9)/3 -> 0.9 | E9: =B9+2*(C9-B9)/3 -> 1.7
A12: sepall | B12: sepall_cat | C12: sepalw | D12: sepalw_cat | E12: petall | F12: petall_cat | G12: petalw | H12: petalw_cat | I12: clase
A13: =iris_data_csv!A3 -> 5.1 | B13: =IF(A13<=$D$6,"chico",IF(A13<=$E$6,"mediano","grande")) -> chico | C13: =iris_data_csv!B3 -> 3.5 | D13: =IF(C13<=$D$7,"chico",IF(C13<=$E$7,"mediano","grande")) -> mediano | E13: =iris_data_csv!C3 -> 1.4 | F13: =IF(E13<=$D$8,"chico",IF(E13<=$E$8,"mediano","grande")) -> chico | G13: =iris_data_csv!D3 -> 0.2 | H13: =IF(G13<=$D$9,"chico",IF(G13<=$E$9,"mediano","grande")) -> chico | I13: =iris_data_csv!E3 -> Iris-setosa
A14: =iris_data_csv!A4 -> 4.9 | B14: =IF(A14<=$D$6,"chico",IF(A14<=$E$6,"mediano","grande")) -> chico | C14: =iris_data_csv!B4 -> 3 | D14: =IF(C14<=$D$7,"chico",IF(C14<=$E$7,"mediano","grande")) -> mediano | E14: =iris_data_csv!C4 -> 1.4 | F14: =IF(E14<=$D$8,"chico",IF(E14<=$E$8,"mediano","grande")) -> chico | G14: =iris_data_csv!D4 -> 0.2 | H14: =IF(G14<=$D$9,"chico",IF(G14<=$E$9,"mediano","grande")) -> chico | I14: =iris_data_csv!E4 -> Iris-setosa
A15: =iris_data_csv!A5 -> 4.7 | B15: =IF(A15<=$D$6,"chico",IF(A15<=$E$6,"mediano","grande")) -> chico | C15: =iris_data_csv!B5 -> 3.2 | D15: =IF(C15<=$D$7,"chico",IF(C15<=$E$7,"mediano","grande")) -> mediano | E15: =iris_data_csv!C5 -> 1.3 | F15: =IF(E15<=$D$8,"chico",IF(E15<=$E$8,"mediano","grande")) -> chico | G15: =iris_data_csv!D5 -> 0.2 | H15: =IF(G15<=$D$9,"chico",IF(G15<=$E$9,"mediano","grande")) -> chico | I15: =iris_data_csv!E5 -> Iris-setosa
A16: =iris_data_csv!A6 -> 4.6 | B16: =IF(A16<=$D$6,"chico",IF(A16<=$E$6,"mediano","grande")) -> chico | C16: =iris_data_csv!B6 -> 3.1 | D16: =IF(C16<=$D$7,"chico",IF(C16<=$E$7,"mediano","grande")) -> mediano | E16: =iris_data_csv!C6 -> 1.5 | F16: =IF(E16<=$D$8,"chico",IF(E16<=$E$8,"mediano","grande")) -> chico | G16: =iris_data_csv!D6 -> 0.2 | H16: =IF(G16<=$D$9,"chico",IF(G16<=$E$9,"mediano","grande")) -> chico | I16: =iris_data_csv!E6 -> Iris-setosa
A17: =iris_data_csv!A7 -> 5 | B17: =IF(A17<=$D$6,"chico",IF(A17<=$E$6,"mediano","grande")) -> chico | C17: =iris_data_csv!B7 -> 3.6 | D17: =IF(C17<=$D$7,"chico",IF(C17<=$E$7,"mediano","grande")) -> mediano | E17: =iris_data_csv!C7 -> 1.4 | F17: =IF(E17<=$D$8,"chico",IF(E17<=$E$8,"mediano","grande")) -> chico | G17: =iris_data_csv!D7 -> 0.2 | H17: =IF(G17<=$D$9,"chico",IF(G17<=$E$9,"mediano","grande")) -> chico | I17: =iris_data_csv!E7 -> Iris-setosa
A18: =iris_data_csv!A8 -> 5.4 | B18: =IF(A18<=$D$6,"chico",IF(A18<=$E$6,"mediano","grande")) -> chico | C18: =iris_data_csv!B8 -> 3.9 | D18: =IF(C18<=$D$7,"chico",IF(C18<=$E$7,"mediano","grande")) -> grande | E18: =iris_data_csv!C8 -> 1.7 | F18: =IF(E18<=$D$8,"chico",IF(E18<=$E$8,"mediano","grande")) -> chico | G18: =iris_data_csv!D8 -> 0.4 | H18: =IF(G18<=$D$9,"chico",IF(G18<=$E$9,"mediano","grande")) -> chico | I18: =iris_data_csv!E8 -> Iris-setosa
A19: =iris_data_csv!A9 -> 4.6 | B19: =IF(A19<=$D$6,"chico",IF(A19<=$E$6,"mediano","grande")) -> chico | C19: =iris_data_csv!B9 -> 3.4 | D19: =IF(C19<=$D$7,"chico",IF(C19<=$E$7,"mediano","grande")) -> mediano | E19: =iris_data_csv!C9 -> 1.4 | F19: =IF(E19<=$D$8,"chico",IF(E19<=$E$8,"mediano","grande")) -> chico | G19: =iris_data_csv!D9 -> 0.3 | H19: =IF(G19<=$D$9,"chico",IF(G19<=$E$9,"mediano","grande")) -> chico | I19: =iris_data_csv!E9 -> Iris-setosa
A20: =iris_data_csv!A10 -> 5 | B20: =IF(A20<=$D$6,"chico",IF(A20<=$E$6,"mediano","grande")) -> chico | C20: =iris_data_csv!B10 -> 3.4 | D20: =IF(C20<=$D$7,"chico",IF(C20<=$E$7,"mediano","grande")) -> mediano | E20: =iris_data_csv!C10 -> 1.5 | F20: =IF(E20<=$D$8,"chico",IF(E20<=$E$8,"mediano","grande")) -> chico | G20: =iris_data_csv!D10 -> 0.2 | H20: =IF(G20<=$D$9,"chico",IF(G20<=$E$9,"mediano","grande")) -> chico | I20: =iris_data_csv!E10 -> Iris-setosa
A21: =iris_data_csv!A11 -> 4.4 | B21: =IF(A21<=$D$6,"chico",IF(A21<=$E$6,"mediano","grande")) -> chico | C21: =iris_data_csv!B11 -> 2.9 | D21: =IF(C21<=$D$7,"chico",IF(C21<=$E$7,"mediano","grande")) -> mediano | E21: =iris_data_csv!C11 -> 1.4 | F21: =IF(E21<=$D$8,"chico",IF(E21<=$E$8,"mediano","grande")) -> chico | G21: =iris_data_csv!D11 -> 0.2 | H21: =IF(G21<=$D$9,"chico",IF(G21<=$E$9,"mediano","grande")) -> chico | I21: =iris_data_csv!E11 -> Iris-setosa
A22: =iris_data_csv!A12 -> 4.9 | B22: =IF(A22<=$D$6,"chico",IF(A22<=$E$6,"mediano","grande")) -> chico | C22: =iris_data_csv!B12 -> 3.1 | D22: =IF(C22<=$D$7,"chico",IF(C22<=$E$7,"mediano","grande")) -> mediano | E22: =iris_data_csv!C12 -> 1.5 | F22: =IF(E22<=$D$8,"chico",IF(E22<=$E$8,"mediano","grande")) -> chico | G22: =iris_data_csv!D12 -> 0.1 | H22: =IF(G22<=$D$9,"chico",IF(G22<=$E$9,"mediano","grande")) -> chico | I22: =iris_data_csv!E12 -> Iris-setosa
A23: =iris_data_csv!A13 -> 5.4 | B23: =IF(A23<=$D$6,"chico",IF(A23<=$E$6,"mediano","grande")) -> chico | C23: =iris_data_csv!B13 -> 3.7 | D23: =IF(C23<=$D$7,"chico",IF(C23<=$E$7,"mediano","grande")) -> grande | E23: =iris_data_csv!C13 -> 1.5 | F23: =IF(E23<=$D$8,"chico",IF(E23<=$E$8,"mediano","grande")) -> chico | G23: =iris_data_csv!D13 -> 0.2 | H23: =IF(G23<=$D$9,"chico",IF(G23<=$E$9,"mediano","grande")) -> chico | I23: =iris_data_csv!E13 -> Iris-setosa
A24: =iris_data_csv!A14 -> 4.8 | B24: =IF(A24<=$D$6,"chico",IF(A24<=$E$6,"mediano","grande")) -> chico | C24: =iris_data_csv!B14 -> 3.4 | D24: =IF(C24<=$D$7,"chico",IF(C24<=$E$7,"mediano","grande")) -> mediano | E24: =iris_data_csv!C14 -> 1.6 | F24: =IF(E24<=$D$8,"chico",IF(E24<=$E$8,"mediano","grande")) -> chico | G24: =iris_data_csv!D14 -> 0.2 | H24: =IF(G24<=$D$9,"chico",IF(G24<=$E$9,"mediano","grande")) -> chico | I24: =iris_data_csv!E14 -> Iris-setosa
... A162: =iris_data_csv!A152 -> 5.9 | B162: =IF(A162<=$D$6,"chico",IF(A162<=$E$6,"mediano","grande")) -> mediano | C162: =iris_data_csv!B152 -> 3 | D162: =IF(C162<=$D$7,"chico",IF(C162<=$E$7,"mediano","grande")) -> mediano | E162: =iris_data_csv!C152 -> 5.1 | F162: =IF(E162<=$D$8,"chico",IF(E162<=$E$8,"mediano","grande")) -> grande | G162: =iris_data_csv!D152 -> 1.8 | H162: =IF(G162<=$D$9,"chico",IF(G162<=$E$9,"mediano","grande")) -> grande | I162: =iris_data_csv!E152 -> Iris-virginica

Sheet datos
A1: id | B1: sepall | C1: sepalw | D1: petall | E1: petalw | F1: clase
A2: =discretizacion!#REF! -> #REF! | B2: =discretizacion!B13 -> chico | C2: =discretizacion!D13 -> mediano | D2: =discretizacion!F13 -> chico | E2: =discretizacion!H13 -> chico | F2: =discretizacion!I13 -> Iris-setosa
A3: =discretizacion!#REF! -> #REF! | B3: =discretizacion!B14 -> chico | C3: =discretizacion!D14 -> mediano | D3: =discretizacion!F14 -> chico | E3: =discretizacion!H14 -> chico | F3: =discretizacion!I14 -> Iris-setosa
A4: =discretizacion!#REF! -> #REF! | B4: =discretizacion!B15 -> chico | C4: =discretizacion!D15 -> mediano | D4: =discretizacion!F15 -> chico | E4: =discretizacion!H15 -> chico | F4: =discretizacion!I15 -> Iris-setosa
A5: =discretizacion!#REF! -> #REF! | B5: =discretizacion!B16 -> chico | C5: =discretizacion!D16 -> mediano | D5: =discretizacion!F16 -> chico | E5: =discretizacion!H16 -> chico | F5: =discretizacion!I16 -> Iris-setosa
A6: =discretizacion!#REF! -> #REF! | B6: =discretizacion!B17 -> chico | C6: =discretizacion!D17 -> mediano | D6: =discretizacion!F17 -> chico | E6: =discretizacion!H17 -> chico | F6: =discretizacion!I17 -> Iris-setosa
A7: =discretizacion!#REF! -> #REF! | B7: =discretizacion!B18 -> chico | C7: =discretizacion!D18 -> grande | D7: =discretizacion!F18 -> chico | E7: =discretizacion!H18 -> chico | F7: =discretizacion!I18 -> Iris-setosa
A8: =discretizacion!#REF! -> #REF! | B8: =discretizacion!B19 -> chico | C8: =discretizacion!D19 -> mediano | D8: =discretizacion!F19 -> chico | E8: =discretizacion!H19 -> chico | F8: =discretizacion!I19 -> Iris-setosa
A9: =discretizacion!#REF! -> #REF! | B9: =discretizacion!B20 -> chico | C9: =discretizacion!D20 -> mediano | D9: =discretizacion!F20 -> chico | E9: =discretizacion!H20 -> chico | F9: =discretizacion!I20 -> Iris-setosa
A10: =discretizacion!#REF! -> #REF! | B10: =discretizacion!B21 -> chico | C10: =discretizacion!D21 -> mediano | D10: =discretizacion!F21 -> chico | E10: =discretizacion!H21 -> chico | F10: =discretizacion!I21 -> Iris-setosa
A11: =discretizacion!#REF! -> #REF! | B11: =discretizacion!B22 -> chico | C11: =discretizacion!D22 -> mediano | D11: =discretizacion!F22 -> chico | E11: =discretizacion!H22 -> chico | F11: =discretizacion!I22 -> Iris-setosa
A12: =discretizacion!#REF! -> #REF! | B12: =discretizacion!B23 -> chico | C12: =discretizacion!D23 -> grande | D12: =discretizacion!F23 -> chico | E12: =discretizacion!H23 -> chico | F12: =discretizacion!I23 -> Iris-setosa
A13: =discretizacion!#REF! -> #REF! | B13: =discretizacion!B24 -> chico | C13: =discretizacion!D24 -> mediano | D13: =discretizacion!F24 -> chico | E13: =discretizacion!H24 -> chico | F13: =discretizacion!I24 -> Iris-setosa
... A151: =discretizacion!#REF! -> #REF! | B151: =discretizacion!B162 -> mediano | C151: =discretizacion!D162 -> mediano | D151: =discretizacion!F162 -> grande | E151: =discretizacion!H162 -> grande | F151: =discretizacion!I162 -> Iris-virginica

Sheet raiz_entropia_ganancia
A1: NODO RAIZ
A3: 1) Distribucion de clases en S
A4: clase | B4: cantidad (n) | C4: proporcion p
A5: setosa | B5: =COUNTIF(datos!$F$2:$F$151,"Iris-setosa") -> 50 | C5: =B5/150 -> 0.33333333
A6: versicolor | B6: =COUNTIF(datos!$F$2:$F$151,"Iris-versicolor") -> 50 | C6: =B6/150 -> 0.33333333
A7: virginica | B7: =COUNTIF(datos!$F$2:$F$151,"Iris-virginica") -> 50 | C7: =B7/150 -> 0.33333333
A9: 2) Entropia(S) = -Σ p_i * log2(p_i)
A10: Entropia(S) = | B10: =-(IF(C5=0,0,C5*LOG(C5,2))+IF(C6=0,0,C6*LOG(C6,2))+IF(C7=0,0,C7*LOG(C7,2))) -> 1.5849625
A12: 3) Tablas de frecuencia, entropia por subconjunto y Ganancia, para cada atributo
A14: Atributo: sepall
A15: valor | B15: n(setosa) | C15: n(versicolor) | D15: n(virginica) | E15: n(v) total | F15: p(setosa) | G15: p(versicolor) | H15: p(virginica) | I15: Entropia(Sv)
A16: chico | B16: =COUNTIFS(datos!$B$2:$B$151,"chico",datos!$F$2:$F$151,"Iris-setosa") -> 47 | C16: =COUNTIFS(datos!$B$2:$B$151,"chico",datos!$F$2:$F$151,"Iris-versicolor") -> 11 | D16: =COUNTIFS(datos!$B$2:$B$151,"chico",datos!$F$2:$F$151,"Iris-virginica") -> 1 | E16: =SUM(B16:D16) -> 59 | F16: =IF($E16=0,0,B16/$E16) -> 0.79661017 | G16: =IF($E16=0,0,C16/$E16) -> 0.18644068 | H16: =IF($E16=0,0,D16/$E16) -> 0.016949153 | I16: =-(IF(F16=0,0,F16*LOG(F16,2))+IF(G16=0,0,G16*LOG(G16,2))+IF(H16=0,0,H16*LOG(H16,2))) -> 0.81282231
A17: mediano | B17: =COUNTIFS(datos!$B$2:$B$151,"mediano",datos!$F$2:$F$151,"Iris-setosa") -> 3 | C17: =COUNTIFS(datos!$B$2:$B$151,"mediano",datos!$F$2:$F$151,"Iris-versicolor") -> 36 | D17: =COUNTIFS(datos!$B$2:$B$151,"mediano",datos!$F$2:$F$151,"Iris-virginica") -> 32 | E17: =SUM(B17:D17) -> 71 | F17: =IF($E17=0,0,B17/$E17) -> 0.042253521 | G17: =IF($E17=0,0,C17/$E17) -> 0.50704225 | H17: =IF($E17=0,0,D17/$E17) -> 0.45070423 | I17: =-(IF(F17=0,0,F17*LOG(F17,2))+IF(G17=0,0,G17*LOG(G17,2))+IF(H17=0,0,H17*LOG(H17,2))) -> 1.2078853
A18: grande | B18: =COUNTIFS(datos!$B$2:$B$151,"grande",datos!$F$2:$F$151,"Iris-setosa") -> 0 | C18: =COUNTIFS(datos!$B$2:$B$151,"grande",datos!$F$2:$F$151,"Iris-versicolor") -> 3 | D18: =COUNTIFS(datos!$B$2:$B$151,"grande",datos!$F$2:$F$151,"Iris-virginica") -> 17 | E18: =SUM(B18:D18) -> 20 | F18: =IF($E18=0,0,B18/$E18) -> 0 | G18: =IF($E18=0,0,C18/$E18) -> 0.15 | H18: =IF($E18=0,0,D18/$E18) -> 0.85 | I18: =-(IF(F18=0,0,F18*LOG(F18,2))+IF(G18=0,0,G18*LOG(G18,2))+IF(H18=0,0,H18*LOG(H18,2))) -> 0.6098403
A19: Entropia ponderada despues de dividir = | E19: =SUMPRODUCT(E16:E18,I16:I18)/150 -> 0.97275453
A20: GANANCIA Gain(S,sepall) = | E20: =B10-E19 -> 0.61220797
A23: Atributo: sepalw
A24: valor | B24: n(setosa) | C24: n(versicolor) | D24: n(virginica) | E24: n(v) total | F24: p(setosa) | G24: p(versicolor) | H24: p(virginica) | I24: Entropia(Sv)
A25: chico | B25: =COUNTIFS(datos!$C$2:$C$151,"chico",datos!$F$2:$F$151,"Iris-setosa") -> 1 | C25: =COUNTIFS(datos!$C$2:$C$151,"chico",datos!$F$2:$F$151,"Iris-versicolor") -> 27 | D25: =COUNTIFS(datos!$C$2:$C$151,"chico",datos!$F$2:$F$151,"Iris-virginica") -> 19 | E25: =SUM(B25:D25) -> 47 | F25: =IF($E25=0,0,B25/$E25) -> 0.021276596 | G25: =IF($E25=0,0,C25/$E25) -> 0.57446809 | H25: =IF($E25=0,0,D25/$E25) -> 0.40425532 | I25: =-(IF(F25=0,0,F25*LOG(F25,2))+IF(G25=0,0,G25*LOG(G25,2))+IF(H25=0,0,H25*LOG(H25,2))) -> 1.1058104
A26: mediano | B26: =COUNTIFS(datos!$C$2:$C$151,"mediano",datos!$F$2:$F$151,"Iris-setosa") -> 36 | C26: =COUNTIFS(datos!$C$2:$C$151,"mediano",datos!$F$2:$F$151,"Iris-versicolor") -> 23 | D26: =COUNTIFS(datos!$C$2:$C$151,"mediano",datos!$F$2:$F$151,"Iris-virginica") -> 29 | E26: =SUM(B26:D26) -> 88 | F26: =IF($E26=0,0,B26/$E26) -> 0.40909091 | G26: =IF($E26=0,0,C26/$E26) -> 0.26136364 | H26: =IF($E26=0,0,D26/$E26) -> 0.32954545 | I26: =-(IF(F26=0,0,F26*LOG(F26,2))+IF(G26=0,0,G26*LOG(G26,2))+IF(H26=0,0,H26*LOG(H26,2))) -> 1.5612421
A27: grande | B27: =COUNTIFS(datos!$C$2:$C$151,"grande",datos!$F$2:$F$151,"Iris-setosa") -> 13 | C27: =COUNTIFS(datos!$C$2:$C$151,"grande",datos!$F$2:$F$151,"Iris-versicolor") -> 0 | D27: =COUNTIFS(datos!$C$2:$C$151,"grande",datos!$F$2:$F$151,"Iris-virginica") -> 2 | E27: =SUM(B27:D27) -> 15 | F27: =IF($E27=0,0,B27/$E27) -> 0.86666667 | G27: =IF($E27=0,0,C27/$E27) -> 0 | H27: =IF($E27=0,0,D27/$E27) -> 0.13333333 | I27: =-(IF(F27=0,0,F27*LOG(F27,2))+IF(G27=0,0,G27*LOG(G27,2))+IF(H27=0,0,H27*LOG(H27,2))) -> 0.56650951
A28: Entropia ponderada despues de dividir = | E28: =SUMPRODUCT(E25:E27,I25:I27)/150 -> 1.3190669
A29: GANANCIA Gain(S,sepalw) = | E29: =B10-E28 -> 0.26589556
A32: Atributo: petall
A33: valor | B33: n(setosa) | C33: n(versicolor) | D33: n(virginica) | E33: n(v) total | F33: p(setosa) | G33: p(versicolor) | H33: p(virginica) | I33: Entropia(Sv)
A34: chico | B34: =COUNTIFS(datos!$D$2:$D$151,"chico",datos!$F$2:$F$151,"Iris-setosa") -> 50 | C34: =COUNTIFS(datos!$D$2:$D$151,"chico",datos!$F$2:$F$151,"Iris-versicolor") -> 0 | D34: =COUNTIFS(datos!$D$2:$D$151,"chico",datos!$F$2:$F$151,"Iris-virginica") -> 0 | E34: =SUM(B34:D34) -> 50 | F34: =IF($E34=0,0,B34/$E34) -> 1 | G34: =IF($E34=0,0,C34/$E34) -> 0 | H34: =IF($E34=0,0,D34/$E34) -> 0 | I34: =-(IF(F34=0,0,F34*LOG(F34,2))+IF(G34=0,0,G34*LOG(G34,2))+IF(H34=0,0,H34*LOG(H34,2))) -> 0
A35: mediano | B35: =COUNTIFS(datos!$D$2:$D$151,"mediano",datos!$F$2:$F$151,"Iris-setosa") -> 0 | C35: =COUNTIFS(datos!$D$2:$D$151,"mediano",datos!$F$2:$F$151,"Iris-versicolor") -> 48 | D35: =COUNTIFS(datos!$D$2:$D$151,"mediano",datos!$F$2:$F$151,"Iris-virginica") -> 6 | E35: =SUM(B35:D35) -> 54 | F35: =IF($E35=0,0,B35/$E35) -> 0 | G35: =IF($E35=0,0,C35/$E35) -> 0.88888889 | H35: =IF($E35=0,0,D35/$E35) -> 0.11111111 | I35: =-(IF(F35=0,0,F35*LOG(F35,2))+IF(G35=0,0,G35*LOG(G35,2))+IF(H35=0,0,H35*LOG(H35,2))) -> 0.50325833
A36: grande | B36: =COUNTIFS(datos!$D$2:$D$151,"grande",datos!$F$2:$F$151,"Iris-setosa") -> 0 | C36: =COUNTIFS(datos!$D$2:$D$151,"grande",datos!$F$2:$F$151,"Iris-versicolor") -> 2 | D36: =COUNTIFS(datos!$D$2:$D$151,"grande",datos!$F$2:$F$151,"Iris-virginica") -> 44 | E36: =SUM(B36:D36) -> 46 | F36: =IF($E36=0,0,B36/$E36) -> 0 | G36: =IF($E36=0,0,C36/$E36) -> 0.043478261 | H36: =IF($E36=0,0,D36/$E36) -> 0.95652174 | I36: =-(IF(F36=0,0,F36*LOG(F36,2))+IF(G36=0,0,G36*LOG(G36,2))+IF(H36=0,0,H36*LOG(H36,2))) -> 0.25801867
A37: Entropia ponderada despues de dividir = | E37: =SUMPRODUCT(E34:E36,I34:I36)/150 -> 0.26029873
A38: GANANCIA Gain(S,petall) = | E38: =B10-E37 -> 1.3246638
A41: Atributo: petalw
A42: valor | B42: n(setosa) | C42: n(versicolor) | D42: n(virginica) | E42: n(v) total | F42: p(setosa) | G42: p(versicolor) | H42: p(virginica) | I42: Entropia(Sv)
A43: chico | B43: =COUNTIFS(datos!$E$2:$E$151,"chico",datos!$F$2:$F$151,"Iris-setosa") -> 50 | C43: =COUNTIFS(datos!$E$2:$E$151,"chico",datos!$F$2:$F$151,"Iris-versicolor") -> 0 | D43: =COUNTIFS(datos!$E$2:$E$151,"chico",datos!$F$2:$F$151,"Iris-virginica") -> 0 | E43: =SUM(B43:D43) -> 50 | F43: =IF($E43=0,0,B43/$E43) -> 1 | G43: =IF($E43=0,0,C43/$E43) -> 0 | H43: =IF($E43=0,0,D43/$E43) -> 0 | I43: =-(IF(F43=0,0,F43*LOG(F43,2))+IF(G43=0,0,G43*LOG(G43,2))+IF(H43=0,0,H43*LOG(H43,2))) -> 0
A44: mediano | B44: =COUNTIFS(datos!$E$2:$E$151,"mediano",datos!$F$2:$F$151,"Iris-setosa") -> 0 | C44: =COUNTIFS(datos!$E$2:$E$151,"mediano",datos!$F$2:$F$151,"Iris-versicolor") -> 49 | D44: =COUNTIFS(datos!$E$2:$E$151,"mediano",datos!$F$2:$F$151,"Iris-virginica") -> 5 | E44: =SUM(B44:D44) -> 54 | F44: =IF($E44=0,0,B44/$E44) -> 0 | G44: =IF($E44=0,0,C44/$E44) -> 0.90740741 | H44: =IF($E44=0,0,D44/$E44) -> 0.092592593 | I44: =-(IF(F44=0,0,F44*LOG(F44,2))+IF(G44=0,0,G44*LOG(G44,2))+IF(H44=0,0,H44*LOG(H44,2))) -> 0.44506486
A45: grande | B45: =COUNTIFS(datos!$E$2:$E$151,"grande",datos!$F$2:$F$151,"Iris-setosa") -> 0 | C45: =COUNTIFS(datos!$E$2:$E$151,"grande",datos!$F$2:$F$151,"Iris-versicolor") -> 1 | D45: =COUNTIFS(datos!$E$2:$E$151,"grande",datos!$F$2:$F$151,"Iris-virginica") -> 45 | E45: =SUM(B45:D45) -> 46 | F45: =IF($E45=0,0,B45/$E45) -> 0 | G45: =IF($E45=0,0,C45/$E45) -> 0.02173913 | H45: =IF($E45=0,0,D45/$E45) -> 0.97826087 | I45: =-(IF(F45=0,0,F45*LOG(F45,2))+IF(G45=0,0,G45*LOG(G45,2))+IF(H45=0,0,H45*LOG(H45,2))) -> 0.15109697
A46: Entropia ponderada despues de dividir = | E46: =SUMPRODUCT(E43:E45,I43:I45)/150 -> 0.20655975
A47: GANANCIA Gain(S,petalw) = | E47: =B10-E46 -> 1.3784027
A50: 4) Comparacion de ganancias — el atributo raiz es el de MAYOR ganancia
A51: atributo | B51: Ganancia
A52: sepall | B52: =E20 -> 0.61220797
...

Sheet nivel2_petalw_mediano_grande
A1: NIVEL 2 — Sub-arboles de las ramas petalw=mediano y petalw=grande (atributo restante con mayor ganancia)
A3: Rama: petalw = mediano
A4: clase | B4: cantidad (n) | C4: proporcion p
A5: setosa | B5: =COUNTIFS(datos!$E$2:$E$151,"mediano",datos!$F$2:$F$151,"Iris-setosa") -> 0 | C5: =IF($B$8=0,0,B5/$B$8) -> 0
A6: versicolor | B6: =COUNTIFS(datos!$E$2:$E$151,"mediano",datos!$F$2:$F$151,"Iris-versicolor") -> 49 | C6: =IF($B$8=0,0,B6/$B$8) -> 0.90740741
A7: virginica | B7: =COUNTIFS(datos!$E$2:$E$151,"mediano",datos!$F$2:$F$151,"Iris-virginica") -> 5 | C7: =IF($B$8=0,0,B7/$B$8) -> 0.092592593
A8: total n(v) | B8: =SUM(B5:B7) -> 54
A9: Entropia(rama) = | B9: =-(IF(C5=0,0,C5*LOG(C5,2))+IF(C6=0,0,C6*LOG(C6,2))+IF(C7=0,0,C7*LOG(C7,2))) -> 0.44506486
A11: Sub-atributo: sepall
A12: valor | B12: n(setosa) | C12: n(versicolor) | D12: n(virginica) | E12: n(v) total | F12: p(setosa) | G12: p(versicolor) | H12: p(virginica) | I12: Entropia(Sv)
A13: chico | B13: =COUNTIFS(datos!$E$2:$E$151,"mediano",datos!$B$2:$B$151,"chico",datos!$F$2:$F$151,"Iris-setosa") -> 0 | C13: =COUNTIFS(datos!$E$2:$E$151,"mediano",datos!$B$2:$B$151,"chico",datos!$F$2:$F$151,"Iris-versicolor") -> 11 | D13: =COUNTIFS(datos!$E$2:$E$151,"mediano",datos!$B$2:$B$151,"chico",datos!$F$2:$F$151,"Iris-virginica") -> 1 | E13: =SUM(B13:D13) -> 12 | F13: =IF($E13=0,0,B13/$E13) -> 0 | G13: =IF($E13=0,0,C13/$E13) -> 0.91666667 | H13: =IF($E13=0,0,D13/$E13) -> 0.083333333 | I13: =-(IF(F13=0,0,F13*LOG(F13,2))+IF(G13=0,0,G13*LOG(G13,2))+IF(H13=0,0,H13*LOG(H13,2))) -> 0.41381685
A14: mediano | B14: =COUNTIFS(datos!$E$2:$E$151,"mediano",datos!$B$2:$B$151,"mediano",datos!$F$2:$F$151,"Iris-setosa") -> 0 | C14: =COUNTIFS(datos!$E$2:$E$151,"mediano",datos!$B$2:$B$151,"mediano",datos!$F$2:$F$151,"Iris-versicolor") -> 35 | D14: =COUNTIFS(datos!$E$2:$E$151,"mediano",datos!$B$2:$B$151,"mediano",datos!$F$2:$F$151,"Iris-virginica") -> 3 | E14: =SUM(B14:D14) -> 38 | F14: =IF($E14=0,0,B14/$E14) -> 0 | G14: =IF($E14=0,0,C14/$E14) -> 0.92105263 | H14: =IF($E14=0,0,D14/$E14) -> 0.078947368 | I14: =-(IF(F14=0,0,F14*LOG(F14,2))+IF(G14=0,0,G14*LOG(G14,2))+IF(H14=0,0,H14*LOG(H14,2))) -> 0.39845927
A15: grande | B15: =COUNTIFS(datos!$E$2:$E$151,"mediano",datos!$B$2:$B$151,"grande",datos!$F$2:$F$151,"Iris-setosa") -> 0 | C15: =COUNTIFS(datos!$E$2:$E$151,"mediano",datos!$B$2:$B$151,"grande",datos!$F$2:$F$151,"Iris-versicolor") -> 3 | D15: =COUNTIFS(datos!$E$2:$E$151,"mediano",datos!$B$2:$B$151,"grande",datos!$F$2:$F$151,"Iris-virginica") -> 1 | E15: =SUM(B15:D15) -> 4 | F15: =IF($E15=0,0,B15/$E15) -> 0 | G15: =IF($E15=0,0,C15/$E15) -> 0.75 | H15: =IF($E15=0,0,D15/$E15) -> 0.25 | I15: =-(IF(F15=0,0,F15*LOG(F15,2))+IF(G15=0,0,G15*LOG(G15,2))+IF(H15=0,0,H15*LOG(H15,2))) -> 0.81127812
A16: Entropia ponderada despues = | E16: =SUMPRODUCT(E13:E15,I13:I15)/$B$8 -> 0.43245124
A17: GANANCIA Gain(rama,sepall) = | E17: =B9-E16 -> 0.012613614
A19: Sub-atributo: sepalw
A20: valor | B20: n(setosa) | C20: n(versicolor) | D20: n(virginica) | E20: n(v) total | F20: p(setosa) | G20: p(versicolor) | H20: p(virginica) | I20: Entropia(Sv)
A21: chico | B21: =COUNTIFS(datos!$E$2:$E$151,"mediano",datos!$C$2:$C$151,"chico",datos!$F$2:$F$151,"Iris-setosa") -> 0 | C21: =COUNTIFS(datos!$E$2:$E$151,"mediano",datos!$C$2:$C$151,"chico",datos!$F$2:$F$151,"Iris-versicolor") -> 27 | D21: =COUNTIFS(datos!$E$2:$E$151,"mediano",datos!$C$2:$C$151,"chico",datos!$F$2:$F$151,"Iris-virginica") -> 4 | E21: =SUM(B21:D21) -> 31 | F21: =IF($E21=0,0,B21/$E21) -> 0 | G21: =IF($E21=0,0,C21/$E21) -> 0.87096774 | H21: =IF($E21=0,0,D21/$E21) -> 0.12903226 | I21: =-(IF(F21=0,0,F21*LOG(F21,2))+IF(G21=0,0,G21*LOG(G21,2))+IF(H21=0,0,H21*LOG(H21,2))) -> 0.55477816
A22: mediano | B22: =COUNTIFS(datos!$E$2:$E$151,"mediano",datos!$C$2:$C$151,"mediano",datos!$F$2:$F$151,"Iris-setosa") -> 0 | C22: =COUNTIFS(datos!$E$2:$E$151,"mediano",datos!$C$2:$C$151,"mediano",datos!$F$2:$F$151,"Iris-versicolor") -> 22 | D22: =COUNTIFS(datos!$E$2:$E$151,"mediano",datos!$C$2:$C$151,"mediano",datos!$F$2:$F$151,"Iris-virginica") -> 1 | E22: =SUM(B22:D22) -> 23 | F22: =IF($E22=0,0,B22/$E22) -> 0 | G22: =IF($E22=0,0,C22/$E22) -> 0.95652174 | H22: =IF($E22=0,0,D22/$E22) -> 0.043478261 | I22: =-(IF(F22=0,0,F22*LOG(F22,2))+IF(G22=0,0,G22*LOG(G22,2))+IF(H22=0,0,H22*LOG(H22,2))) -> 0.25801867
A23: grande | B23: =COUNTIFS(datos!$E$2:$E$151,"mediano",datos!$C$2:$C$151,"grande",datos!$F$2:$F$151,"Iris-setosa") -> 0 | C23: =COUNTIFS(datos!$E$2:$E$151,"mediano",datos!$C$2:$C$151,"grande",datos!$F$2:$F$151,"Iris-versicolor") -> 0 | D23: =COUNTIFS(datos!$E$2:$E$151,"mediano",datos!$C$2:$C$151,"grande",datos!$F$2:$F$151,"Iris-virginica") -> 0 | E23: =SUM(B23:D23) -> 0 | F23: =IF($E23=0,0,B23/$E23) -> 0 | G23: =IF($E23=0,0,C23/$E23) -> 0 | H23: =IF($E23=0,0,D23/$E23) -> 0 | I23: =-(IF(F23=0,0,F23*LOG(F23,2))+IF(G23=0,0,G23*LOG(G23,2))+IF(H23=0,0,H23*LOG(H23,2))) -> 0
A24: Entropia ponderada despues = | E24: =SUMPRODUCT(E21:E23,I21:I23)/$B$8 -> 0.4283806
A25: GANANCIA Gain(rama,sepalw) = | E25: =B9-E24 -> 0.016684256
A27: Sub-atributo: petall
A28: valor | B28: n(setosa) | C28: n(versicolor) | D28: n(virginica) | E28: n(v) total | F28: p(setosa) | G28: p(versicolor) | H28: p(virginica) | I28: Entropia(Sv)
A29: chico | B29: =COUNTIFS(datos!$E$2:$E$151,"mediano",datos!$D$2:$D$151,"chico",datos!$F$2:$F$151,"Iris-setosa") -> 0 | C29: =COUNTIFS(datos!$E$2:$E$151,"mediano",datos!$D$2:$D$151,"chico",datos!$F$2:$F$151,"Iris-versicolor") -> 0 | D29: =COUNTIFS(datos!$E$2:$E$151,"mediano",datos!$D$2:$D$151,"chico",datos!$F$2:$F$151,"Iris-virginica") -> 0 | E29: =SUM(B29:D29) -> 0 | F29: =IF($E29=0,0,B29/$E29) -> 0 | G29: =IF($E29=0,0,C29/$E29) -> 0 | H29: =IF($E29=0,0,D29/$E29) -> 0 | I29: =-(IF(F29=0,0,F29*LOG(F29,2))+IF(G29=0,0,G29*LOG(G29,2))+IF(H29=0,0,H29*LOG(H29,2))) -> 0
A30: mediano | B30: =COUNTIFS(datos!$E$2:$E$151,"mediano",datos!$D$2:$D$151,"mediano",datos!$F$2:$F$151,"Iris-setosa") -> 0 | C30: =COUNTIFS(datos!$E$2:$E$151,"mediano",datos!$D$2:$D$151,"mediano",datos!$F$2:$F$151,"Iris-versicolor") -> 47 | D30: =COUNTIFS(datos!$E$2:$E$151,"mediano",datos!$D$2:$D$151,"mediano",datos!$F$2:$F$151,"Iris-virginica") -> 1 | E30: =SUM(B30:D30) -> 48 | F30: =IF($E30=0,0,B30/$E30) -> 0 | G30: =IF($E30=0,0,C30/$E30) -> 0.97916667 | H30: =IF($E30=0,0,D30/$E30) -> 0.020833333 | I30: =-(IF(F30=0,0,F30*LOG(F30,2))+IF(G30=0,0,G30*LOG(G30,2))+IF(H30=0,0,H30*LOG(H30,2))) -> 0.14609425
A31: grande | B31: =COUNTIFS(datos!$E$2:$E$151,"mediano",datos!$D$2:$D$151,"grande",datos!$F$2:$F$151,"Iris-setosa") -> 0 | C31: =COUNTIFS(datos!$E$2:$E$151,"mediano",datos!$D$2:$D$151,"grande",datos!$F$2:$F$151,"Iris-versicolor") -> 2 | D31: =COUNTIFS(datos!$E$2:$E$151,"mediano",datos!$D$2:$D$151,"grande",datos!$F$2:$F$151,"Iris-virginica") -> 4 | E31: =SUM(B31:D31) -> 6 | F31: =IF($E31=0,0,B31/$E31) -> 0 | G31: =IF($E31=0,0,C31/$E31) -> 0.33333333 | H31: =IF($E31=0,0,D31/$E31) -> 0.66666667 | I31: =-(IF(F31=0,0,F31*LOG(F31,2))+IF(G31=0,0,G31*LOG(G31,2))+IF(H31=0,0,H31*LOG(H31,2))) -> 0.91829583
A32: Entropia ponderada despues = | E32: =SUMPRODUCT(E29:E31,I29:I31)/$B$8 -> 0.23189443
A33: GANANCIA Gain(rama,petall) = | E33: =B9-E32 -> 0.21317043
A35: Comparacion de ganancias en esta rama:
A36: atributo | B36: Ganancia
A37: sepall | B37: =E17 -> 0.012613614
A38: sepalw | B38: =E25 -> 0.016684256
A39: petall | B39: =E33 -> 0.21317043
A40: Atributo elegido para petalw=mediano = | B40: =INDEX(A37:A39,MATCH(MAX(B37:B39),B37:B39,0)) -> petall
A43: Rama: petalw = grande
A44: clase | B44: cantidad (n) | C44: proporcion p
A45: setosa | B45: =COUNTIFS(datos!$E$2:$E$151,"grande",datos!$F$2:$F$151,"Iris-setosa") -> 0 | C45: =IF($B$48=0,0,B45/$B$48) -> 0
A46: versicolor | B46: =COUNTIFS(datos!$E$2:$E$151,"grande",datos!$F$2:$F$151,"Iris-versicolor") -> 1 | C46: =IF($B$48=0,0,B46/$B$48) -> 0.02173913
A47: virginica | B47: =COUNTIFS(datos!$E$2:$E$151,"grande",datos!$F$2:$F$151,"Iris-virginica") -> 45 | C47: =IF($B$48=0,0,B47/$B$48) -> 0.97826087
...

Sheet arbol_resultado
A1: ARBOL ID3 COMPLETO (sin poda) — recorrido nivel por nivel
A2: Nivel | B2: Regla (ruta desde la raiz) | C2: n (instancias) | D2: Tipo | E2: Decision / Atributo de division | F2: Nota
A3: 0 | B3: (S completo) | C3: 150 | D3: NODO | E3: divide por: petalw (entropia=1.5850, ganancia=1.3784)
A4: 1 | B4: petalw = chico | C4: 50 | D4: HOJA | E4: setosa | F4: entropia 0, todos la misma clase
A5: 1 | B5: petalw = mediano | C5: 54 | D5: NODO | E5: divide por: petall (entropia=0.4451, ganancia=0.2132)
A6: 2 | B6: petall = chico | C6: 0 | D6: HOJA | E6: versicolor | F6: subconjunto vacio -> clase mayoritaria del padre
A7: 2 | B7: petall = mediano | C7: 48 | D7: NODO | E7: divide por: sepall (entropia=0.1461, ganancia=0.0426)
A8: 3 | B8: sepall = chico | C8: 12 | D8: NODO | E8: divide por: sepalw (entropia=0.4138, ganancia=0.0109)
A9: 4 | B9: sepalw = chico | C9: 11 | D9: HOJA | E9: versicolor | F9: sin atributos restantes -> clase mayoritaria
A10: 4 | B10: sepalw = mediano | C10: 1 | D10: HOJA | E10: versicolor | F10: entropia 0, todos la misma clase
A11: 4 | B11: sepalw = grande | C11: 0 | D11: HOJA | E11: versicolor | F11: subconjunto vacio -> clase mayoritaria del padre
A12: 3 | B12: sepall = mediano | C12: 33 | D12: HOJA | E12: versicolor | F12: entropia 0, todos la misma clase
A13: 3 | B13: sepall = grande | C13: 3 | D13: HOJA | E13: versicolor | F13: entropia 0, todos la misma clase
A14: 2 | B14: petall = grande | C14: 6 | D14: NODO | E14: divide por: sepall (entropia=0.9183, ganancia=0.1092)
A15: 3 | B15: sepall = chico | C15: 0 | D15: HOJA | E15: virginica | F15: subconjunto vacio -> clase mayoritaria del padre
A16: 3 | B16: sepall = mediano | C16: 5 | D16: NODO | E16: divide por: sepalw (entropia=0.9710, ganancia=0.3219)
A17: 4 | B17: sepalw = chico | C17: 4 | D17: HOJA | E17: virginica | F17: sin atributos restantes -> clase mayoritaria
A18: 4 | B18: sepalw = mediano | C18: 1 | D18: HOJA | E18: versicolor | F18: entropia 0, todos la misma clase
A19: 4 | B19: sepalw = grande | C19: 0 | D19: HOJA | E19: virginica | F19: subconjunto vacio -> clase mayoritaria del padre
A20: 3 | B20: sepall = grande | C20: 1 | D20: HOJA | E20: virginica | F20: entropia 0, todos la misma clase
A21: 1 | B21: petalw = grande | C21: 46 | D21: NODO | E21: divide por: petall (entropia=0.1511, ganancia=0.0663)
A22: 2 | B22: petall = chico | C22: 0 | D22: HOJA | E22: virginica | F22: subconjunto vacio -> clase mayoritaria del padre
A23: 2 | B23: petall = mediano | C23: 6 | D23: NODO | E23: divide por: sepalw (entropia=0.6500, ganancia=0.1909)
A24: 3 | B24: sepalw = chico | C24: 3 | D24: HOJA | E24: virginica | F24: entropia 0, todos la misma clase
A25: 3 | B25: sepalw = mediano | C25: 3 | D25: NODO | E25: divide por: sepall (entropia=0.9183, ganancia=0.0000)
A26: 4 | B26: sepall = chico | C26: 0 | D26: HOJA | E26: virginica | F26: subconjunto vacio -> clase mayoritaria del padre
A27: 4 | B27: sepall = mediano | C27: 3 | D27: HOJA | E27: virginica | F27: sin atributos restantes -> clase mayoritaria
A28: 4 | B28: sepall = grande | C28: 0 | D28: HOJA | E28: virginica | F28: subconjunto vacio -> clase mayoritaria del padre
A29: 3 | B29: sepalw = grande | C29: 0 | D29: HOJA | E29: virginica | F29: subconjunto vacio -> clase mayoritaria del padre
A30: 2 | B30: petall = grande | C30: 40 | D30: HOJA | E30: virginica | F30: entropia 0, todos la misma clase

Sheet evaluacion_clasificacion
A1: EVALUACION — clasificacion de las 150 instancias con el arbol ID3 y matriz de confusion
A2: id | B2: sepall | C2: sepalw | D2: petall | E2: petalw | F2: clase real
A3: 1 | B3: chico | C3: mediano | D3: chico | E3: chico | F3: Iris-setosa
A4: 2 | B4: chico | C4: mediano | D4: chico | E4: chico | F4: Iris-setosa
A5: 3 | B5: chico | C5: mediano | D5: chico | E5: chico | F5: Iris-setosa
A6: 4 | B6: chico | C6: mediano | D6: chico | E6: chico | F6: Iris-setosa
A7: 5 | B7: chico | C7: mediano | D7: chico | E7: chico | F7: Iris-setosa
A8: 6 | B8: chico | C8: grande | D8: chico | E8: chico | F8: Iris-setosa
A9: 7 | B9: chico | C9: mediano | D9: chico | E9: chico | F9: Iris-setosa
A10: 8 | B10: chico | C10: mediano | D10: chico | E10: chico | F10: Iris-setosa
A11: 9 | B11: chico | C11: mediano | D11: chico | E11: chico | F11: Iris-setosa
A12: 10 | B12: chico | C12: mediano | D12: chico | E12: chico | F12: Iris-setosa
A13: 11 | B13: chico | C13: grande | D13: chico | E13: chico | F13: Iris-setosa
A14: 12 | B14: chico | C14: mediano | D14: chico | E14: chico | F14: Iris-setosa
... A152: 150 | B152: mediano | C152: mediano | D152: grande | E152: grande | F152: Iris-virginica
